log_setup.py | [INFO] | 2021-11-08 22:43:59,868 | __main__ | : Log Setup Completed, called from weather_open in log_setup:54
weather_open.py | [INFO] | 2021-11-08 22:44:00,023 | __main__ | : Inizio in weather_open:51
weather_open.py | [INFO] | 2021-11-08 22:44:00,517 | __main__ | : Fine in weather_open:60
log_setup.py | [INFO] | 2021-11-08 22:47:11,849 | __main__ | : Log Setup Completed, called from weather_open in log_setup:54
weather_open.py | [INFO] | 2021-11-08 22:47:12,163 | __main__ | : Inizio in weather_open:57
weather_open.py | [INFO] | 2021-11-08 22:47:12,529 | __main__ | : Fine in weather_open:66
log_setup.py | [INFO] | 2021-11-08 22:53:26,728 | __main__ | : Log Setup Completed, called from weather_open in log_setup:54
weather_open.py | [INFO] | 2021-11-08 22:53:26,944 | __main__ | : Inizio in weather_open:59
weather_open.py | [INFO] | 2021-11-08 22:53:27,296 | __main__ | : Fine in weather_open:68
log_setup.py | [INFO] | 2021-11-08 22:53:48,317 | __main__ | : Log Setup Completed, called from weather_open in log_setup:54
weather_open.py | [INFO] | 2021-11-08 22:53:48,477 | __main__ | : Inizio in weather_open:59
weather_open.py | [INFO] | 2021-11-08 22:53:48,872 | __main__ | : Fine in weather_open:68
log_setup.py | [INFO] | 2021-11-08 22:54:28,334 | __main__ | : Log Setup Completed, called from weather_open in log_setup:54
weather_open.py | [INFO] | 2021-11-08 22:54:28,457 | __main__ | : Inizio in weather_open:59
weather_open.py | [INFO] | 2021-11-08 22:54:28,798 | __main__ | : Fine in weather_open:68
log_setup.py | [INFO] | 2021-11-18 21:44:49,730 | __main__ | : Log Setup Completed, called from weather_open in log_setup:54
weather_open.py | [INFO] | 2021-11-18 21:44:52,525 | __main__ | : Inizio in weather_open:59
weather_open.py | [INFO] | 2021-11-18 21:44:52,960 | __main__ | : Fine in weather_open:68
log_setup.py | [INFO] | 2021-11-18 21:49:06,646 | __main__ | : Log Setup Completed, called from weather_open in log_setup:54
weather_open.py | [INFO] | 2021-11-18 21:49:06,815 | __main__ | : Inizio in weather_open:59
weather_open.py | [INFO] | 2021-11-18 21:49:07,260 | __main__ | : Fine in weather_open:68
log_setup.py | [INFO] | 2021-11-18 21:50:44,282 | __main__ | : Log Setup Completed, called from weather_open in log_setup:54
weather_open.py | [INFO] | 2021-11-18 21:50:44,415 | __main__ | : Inizio in weather_open:59
weather_open.py | [INFO] | 2021-11-18 21:50:44,766 | __main__ | : Fine in weather_open:68
log_setup.py | [INFO] | 2021-11-18 21:52:04,430 | __main__ | : Log Setup Completed, called from weather_open in log_setup:54
weather_open.py | [INFO] | 2021-11-18 21:52:04,585 | __main__ | : Inizio in weather_open:59
weather_open.py | [INFO] | 2021-11-18 21:52:05,096 | __main__ | : Fine in weather_open:68
log_setup.py | [INFO] | 2021-11-18 21:52:33,650 | __main__ | : Log Setup Completed, called from weather_open in log_setup:54
weather_open.py | [INFO] | 2021-11-18 21:52:33,785 | __main__ | : Inizio in weather_open:59
weather_open.py | [INFO] | 2021-11-18 21:52:34,253 | __main__ | : Fine in weather_open:68
log_setup.py | [INFO] | 2021-11-18 21:54:32,754 | __main__ | : Log Setup Completed, called from weather_open in log_setup:54
weather_open.py | [INFO] | 2021-11-18 21:54:32,886 | __main__ | : Inizio in weather_open:59
weather_open.py | [INFO] | 2021-11-18 21:54:33,296 | __main__ | : Fine in weather_open:68
log_setup.py | [INFO] | 2021-11-18 21:58:05,605 | __main__ | : Log Setup Completed, called from weather_open in log_setup:54
weather_open.py | [INFO] | 2021-11-18 21:58:05,745 | __main__ | : Inizio in weather_open:59
weather_open.py | [INFO] | 2021-11-18 21:58:06,233 | __main__ | : Fine in weather_open:68
log_setup.py | [INFO] | 2021-11-18 21:59:05,122 | __main__ | : Log Setup Completed, called from weather_open in log_setup:54
weather_open.py | [INFO] | 2021-11-18 21:59:05,250 | __main__ | : Inizio in weather_open:59
weather_open.py | [INFO] | 2021-11-18 21:59:05,617 | __main__ | : Fine in weather_open:68
log_setup.py | [INFO] | 2021-11-18 21:59:44,072 | __main__ | : Log Setup Completed, called from weather_open in log_setup:54
weather_open.py | [INFO] | 2021-11-18 21:59:44,211 | __main__ | : Inizio in weather_open:59
weather_open.py | [INFO] | 2021-11-18 21:59:44,604 | __main__ | : Fine in weather_open:68
log_setup.py | [INFO] | 2021-11-18 22:01:30,537 | __main__ | : Log Setup Completed, called from weather_open in log_setup:54
weather_open.py | [INFO] | 2021-11-18 22:01:30,683 | __main__ | : Inizio in weather_open:61
weather_open.py | [INFO] | 2021-11-18 22:01:31,125 | __main__ | : Fine in weather_open:70
log_setup.py | [INFO] | 2022-02-12 20:41:13,326 | __main__ | : Log Setup Completed, called from weather_open in log_setup:54
weather_open.py | [INFO] | 2022-02-12 20:41:20,071 | __main__ | : Inizio in weather_open:71
weather_open.py | [INFO] | 2022-02-12 20:41:23,332 | __main__ | : Fine in weather_open:80
log_setup.py | [INFO] | 2022-02-12 20:44:33,707 | __main__ | : Log Setup Completed, called from weather_open in log_setup:54
weather_open.py | [INFO] | 2022-02-12 20:44:33,936 | __main__ | : Inizio in weather_open:78
weather_open.py | [CRITICAL] | 2022-02-12 20:44:33,936 | __main__ | : division by zero in weather_open:34
Traceback (most recent call last):
  File "c:/Users/forteg/OneDrive - Fratelli Carli Spa/Desktop/Python/Training/weather_open.py", line 32, in main
    a = 1/0
ZeroDivisionError: division by zero
weather_open.py | [INFO] | 2022-02-12 20:44:41,843 | __main__ | : Fine in weather_open:87
log_setup.py | [INFO] | 2022-02-12 20:51:26,654 | __main__ | : Log Setup Completed, called from weather_open in log_setup:54
weather_open.py | [INFO] | 2022-02-12 20:51:30,340 | __main__ | : Inizio in weather_open:73
weather_open.py | [CRITICAL] | 2022-02-12 20:51:30,340 | __main__ | : division by zero in weather_open:79
Traceback (most recent call last):
  File "c:/Users/forteg/OneDrive - Fratelli Carli Spa/Desktop/Python/Training/weather_open.py", line 77, in <module>
    main()
  File "c:/Users/forteg/OneDrive - Fratelli Carli Spa/Desktop/Python/Training/weather_open.py", line 31, in main
    a = 1/0
ZeroDivisionError: division by zero
weather_open.py | [INFO] | 2022-02-12 20:51:32,918 | __main__ | : Fine in weather_open:82
log_setup.py | [INFO] | 2022-02-12 22:19:15,064 | __main__ | : Log Setup Completed, called from weather_open in log_setup:54
weather_open.py | [INFO] | 2022-02-12 22:19:18,611 | __main__ | : Inizio in weather_open:73
weather_open.py | [INFO] | 2022-02-12 22:19:20,959 | __main__ | : Fine in weather_open:82
log_setup.py | [INFO] | 2022-03-02 22:05:13,381 | __main__ | : Log Setup Completed, called from weather_open in log_setup:54
weather_open.py | [INFO] | 2022-03-02 22:05:20,149 | __main__ | : Inizio in weather_open:73
weather_open.py | [INFO] | 2022-03-02 22:05:22,733 | __main__ | : Fine in weather_open:82
log_setup.py | [INFO] | 2022-03-02 22:18:51,142 | __main__ | : Log Setup Completed, called from weather_open in log_setup:54
log_setup.py | [INFO] | 2022-03-02 22:19:56,365 | __main__ | : Log Setup Completed, called from weather_open in log_setup:54
weather_open.py | [INFO] | 2022-03-02 22:19:56,711 | __main__ | : Inizio in weather_open:93
weather_open.py | [INFO] | 2022-03-02 22:19:56,711 | __main__ | : local variable 'api' referenced before assignment in weather_open:100
Traceback (most recent call last):
  File "c:/Users/forteg/OneDrive - Fratelli Carli Spa/Desktop/Python/Training/weather_open.py", line 97, in <module>
    main()
  File "c:/Users/forteg/OneDrive - Fratelli Carli Spa/Desktop/Python/Training/weather_open.py", line 54, in main
    lat = api[0]["lat"]
UnboundLocalError: local variable 'api' referenced before assignment
weather_open.py | [INFO] | 2022-03-02 22:19:56,719 | __main__ | : Fine in weather_open:104
log_setup.py | [INFO] | 2022-03-02 22:21:08,666 | __main__ | : Log Setup Completed, called from weather_open in log_setup:54
weather_open.py | [INFO] | 2022-03-02 22:21:08,823 | __main__ | : Inizio in weather_open:93
weather_open.py | [INFO] | 2022-03-02 22:21:12,067 | __main__ | : Fine in weather_open:104
log_setup.py | [INFO] | 2022-03-02 22:23:28,344 | __main__ | : Log Setup Completed, called from weather_open in log_setup:54
weather_open.py | [INFO] | 2022-03-02 22:23:28,488 | __main__ | : Inizio in weather_open:93
weather_open.py | [INFO] | 2022-03-02 22:23:31,417 | __main__ | : Fine in weather_open:104
log_setup.py | [INFO] | 2022-03-02 22:26:11,989 | __main__ | : Log Setup Completed, called from weather_open in log_setup:54
weather_open.py | [INFO] | 2022-03-02 22:26:15,698 | __main__ | : Inizio in weather_open:93
weather_open.py | [INFO] | 2022-03-02 22:26:18,583 | __main__ | : Fine in weather_open:104
log_setup.py | [INFO] | 2022-03-02 22:27:30,285 | __main__ | : Log Setup Completed, called from weather_open in log_setup:54
weather_open.py | [INFO] | 2022-03-02 22:27:30,476 | __main__ | : Inizio in weather_open:93
weather_open.py | [INFO] | 2022-03-02 22:27:33,193 | __main__ | : Fine in weather_open:104
log_setup.py | [INFO] | 2022-03-02 22:28:14,876 | __main__ | : Log Setup Completed, called from weather_open in log_setup:54
weather_open.py | [INFO] | 2022-03-02 22:28:15,073 | __main__ | : Inizio in weather_open:93
weather_open.py | [INFO] | 2022-03-02 22:28:15,252 | __main__ | : list index out of range in weather_open:100
Traceback (most recent call last):
  File "c:/Users/forteg/OneDrive - Fratelli Carli Spa/Desktop/Python/Training/weather_open.py", line 97, in <module>
    main()
  File "c:/Users/forteg/OneDrive - Fratelli Carli Spa/Desktop/Python/Training/weather_open.py", line 54, in main
    lat = api[0]["lat"]
IndexError: list index out of range
weather_open.py | [INFO] | 2022-03-02 22:28:15,252 | __main__ | : Fine in weather_open:104
log_setup.py | [INFO] | 2022-03-02 22:29:07,951 | __main__ | : Log Setup Completed, called from weather_open in log_setup:54
weather_open.py | [INFO] | 2022-03-02 22:29:08,130 | __main__ | : Inizio in weather_open:95
weather_open.py | [INFO] | 2022-03-02 22:29:09,897 | __main__ | : Fine in weather_open:106
log_setup.py | [INFO] | 2022-03-02 22:29:54,158 | __main__ | : Log Setup Completed, called from weather_open in log_setup:54
weather_open.py | [INFO] | 2022-03-02 22:29:54,362 | __main__ | : Inizio in weather_open:95
weather_open.py | [INFO] | 2022-03-02 22:29:57,040 | __main__ | : Fine in weather_open:106
log_setup.py | [INFO] | 2022-03-02 22:31:24,374 | __main__ | : Log Setup Completed, called from weather_open in log_setup:54
weather_open.py | [INFO] | 2022-03-02 22:31:24,516 | __main__ | : Inizio in weather_open:95
weather_open.py | [INFO] | 2022-03-02 22:31:27,919 | __main__ | : Fine in weather_open:106
log_setup.py | [INFO] | 2022-03-02 22:33:37,309 | __main__ | : Log Setup Completed, called from weather_open in log_setup:54
weather_open.py | [INFO] | 2022-03-02 22:33:37,452 | __main__ | : Inizio in weather_open:97
weather_open.py | [INFO] | 2022-03-02 22:33:40,474 | __main__ | : Fine in weather_open:108
log_setup.py | [INFO] | 2022-03-02 22:35:22,190 | __main__ | : Log Setup Completed, called from weather_open in log_setup:54
weather_open.py | [INFO] | 2022-03-02 22:35:22,532 | __main__ | : Inizio in weather_open:100
weather_open.py | [INFO] | 2022-03-02 22:35:22,532 | __main__ | : local variable 'api' referenced before assignment in weather_open:107
Traceback (most recent call last):
  File "c:/Users/forteg/OneDrive - Fratelli Carli Spa/Desktop/Python/Training/weather_open.py", line 104, in <module>
    main()
  File "c:/Users/forteg/OneDrive - Fratelli Carli Spa/Desktop/Python/Training/weather_open.py", line 55, in main
    print(f"Numero risultati trovati per {city}: {len(api)}")
UnboundLocalError: local variable 'api' referenced before assignment
weather_open.py | [INFO] | 2022-03-02 22:35:22,549 | __main__ | : Fine in weather_open:111
log_setup.py | [INFO] | 2022-03-02 22:35:57,681 | __main__ | : Log Setup Completed, called from weather_open in log_setup:54
weather_open.py | [INFO] | 2022-03-02 22:35:57,823 | __main__ | : Inizio in weather_open:100
weather_open.py | [INFO] | 2022-03-02 22:36:00,777 | __main__ | : Fine in weather_open:111
log_setup.py | [INFO] | 2022-03-02 22:41:05,937 | __main__ | : Log Setup Completed, called from weather_open in log_setup:54
weather_open.py | [INFO] | 2022-03-02 22:41:09,127 | __main__ | : Inizio in weather_open:100
weather_open.py | [INFO] | 2022-03-02 22:41:12,140 | __main__ | : Fine in weather_open:111
log_setup.py | [INFO] | 2022-03-02 22:47:23,889 | __main__ | : Log Setup Completed, called from weather_open in log_setup:54
weather_open.py | [INFO] | 2022-03-02 22:47:24,038 | __main__ | : Inizio in weather_open:103
weather_open.py | [INFO] | 2022-03-02 22:47:25,967 | __main__ | : 'state' in weather_open:110
Traceback (most recent call last):
  File "c:/Users/forteg/OneDrive - Fratelli Carli Spa/Desktop/Python/Training/weather_open.py", line 107, in <module>
    main()
  File "c:/Users/forteg/OneDrive - Fratelli Carli Spa/Desktop/Python/Training/weather_open.py", line 60, in main
    f"Dati per la prima occorrenza {api[0]['country']} {api[0]['state']}")
KeyError: 'state'
weather_open.py | [INFO] | 2022-03-02 22:47:25,975 | __main__ | : Fine in weather_open:114
log_setup.py | [INFO] | 2022-03-02 22:49:45,308 | __main__ | : Log Setup Completed, called from weather_open in log_setup:54
weather_open.py | [INFO] | 2022-03-02 22:49:45,457 | __main__ | : Inizio in weather_open:107
weather_open.py | [INFO] | 2022-03-02 22:49:47,311 | __main__ | : 'state' in weather_open:114
Traceback (most recent call last):
  File "c:/Users/forteg/OneDrive - Fratelli Carli Spa/Desktop/Python/Training/weather_open.py", line 111, in <module>
    main()
  File "c:/Users/forteg/OneDrive - Fratelli Carli Spa/Desktop/Python/Training/weather_open.py", line 59, in main
    if api[0]['state']:
KeyError: 'state'
weather_open.py | [INFO] | 2022-03-02 22:49:47,319 | __main__ | : Fine in weather_open:118
log_setup.py | [INFO] | 2022-03-02 22:51:31,329 | __main__ | : Log Setup Completed, called from weather_open in log_setup:54
weather_open.py | [INFO] | 2022-03-02 22:51:31,494 | __main__ | : Inizio in weather_open:107
weather_open.py | [INFO] | 2022-03-02 22:51:34,226 | __main__ | : Fine in weather_open:118
log_setup.py | [INFO] | 2022-03-02 22:52:24,104 | __main__ | : Log Setup Completed, called from weather_open in log_setup:54
weather_open.py | [INFO] | 2022-03-02 22:52:24,242 | __main__ | : Inizio in weather_open:107
weather_open.py | [INFO] | 2022-03-02 22:52:26,867 | __main__ | : Fine in weather_open:118
log_setup.py | [INFO] | 2022-03-02 22:53:04,999 | __main__ | : Log Setup Completed, called from weather_open in log_setup:54
weather_open.py | [INFO] | 2022-03-02 22:53:05,146 | __main__ | : Inizio in weather_open:107
weather_open.py | [INFO] | 2022-03-02 22:53:07,972 | __main__ | : Fine in weather_open:118
log_setup.py | [INFO] | 2022-03-02 22:54:35,564 | __main__ | : Log Setup Completed, called from weather_open in log_setup:54
weather_open.py | [INFO] | 2022-03-02 22:54:35,701 | __main__ | : Inizio in weather_open:108
weather_open.py | [INFO] | 2022-03-02 22:54:38,697 | __main__ | : Fine in weather_open:119
log_setup.py | [INFO] | 2022-09-12 22:23:08,141 | __main__ | : Log Setup Completed, called from weather_open in log_setup:54
weather_open.py | [INFO] | 2022-09-12 22:23:08,944 | __main__ | : Inizio in weather_open:108
weather_open.py | [INFO] | 2022-09-12 22:23:12,515 | __main__ | : Fine in weather_open:119
log_setup.py | [INFO] | 2022-09-12 22:24:41,868 | __main__ | : Log Setup Completed, called from weather_open in log_setup:54
weather_open.py | [INFO] | 2022-09-12 22:24:42,195 | __main__ | : Inizio in weather_open:108
weather_open.py | [INFO] | 2022-09-12 22:24:42,195 | __main__ | : tuple index out of range in weather_open:115
Traceback (most recent call last):
  File "c:/Users/forteg/OneDrive - Fratelli Carli Spa/Desktop/Python/Training/api_sample/weather_open.py", line 112, in <module>
    main()
  File "c:/Users/forteg/OneDrive - Fratelli Carli Spa/Desktop/Python/Training/api_sample/weather_open.py", line 55, in main
    api = geocode(city)
  File "c:/Users/forteg/OneDrive - Fratelli Carli Spa/Desktop/Python/Training/api_sample/weather_open.py", line 43, in geocode
    f"http://api.openweathermap.org/geo/1.0/direct?q={city[0]},{city[1]}&limit=5&appid={api_key}")
IndexError: tuple index out of range
weather_open.py | [INFO] | 2022-09-12 22:24:42,209 | __main__ | : Fine in weather_open:119
log_setup.py | [INFO] | 2022-09-12 22:25:33,687 | __main__ | : Log Setup Completed, called from weather_open in log_setup:54
weather_open.py | [INFO] | 2022-09-12 22:25:33,916 | __main__ | : Inizio in weather_open:109
weather_open.py | [INFO] | 2022-09-12 22:25:33,916 | __main__ | : tuple index out of range in weather_open:116
Traceback (most recent call last):
  File "c:/Users/forteg/OneDrive - Fratelli Carli Spa/Desktop/Python/Training/api_sample/weather_open.py", line 113, in <module>
    main()
  File "c:/Users/forteg/OneDrive - Fratelli Carli Spa/Desktop/Python/Training/api_sample/weather_open.py", line 56, in main
    api = geocode(city)
  File "c:/Users/forteg/OneDrive - Fratelli Carli Spa/Desktop/Python/Training/api_sample/weather_open.py", line 44, in geocode
    f"http://api.openweathermap.org/geo/1.0/direct?q={city[0]},{city[1]}&limit=5&appid={api_key}")
IndexError: tuple index out of range
weather_open.py | [INFO] | 2022-09-12 22:25:33,920 | __main__ | : Fine in weather_open:120
log_setup.py | [INFO] | 2022-09-12 22:27:50,061 | __main__ | : Log Setup Completed, called from weather_open in log_setup:54
weather_open.py | [INFO] | 2022-09-12 22:27:50,365 | __main__ | : Inizio in weather_open:109
weather_open.py | [INFO] | 2022-09-12 22:27:50,365 | __main__ | : tuple index out of range in weather_open:116
Traceback (most recent call last):
  File "c:/Users/forteg/OneDrive - Fratelli Carli Spa/Desktop/Python/Training/api_sample/weather_open.py", line 113, in <module>
    main()
  File "c:/Users/forteg/OneDrive - Fratelli Carli Spa/Desktop/Python/Training/api_sample/weather_open.py", line 56, in main
    api = geocode(city)
  File "c:/Users/forteg/OneDrive - Fratelli Carli Spa/Desktop/Python/Training/api_sample/weather_open.py", line 44, in geocode
    f"http://api.openweathermap.org/geo/1.0/direct?q={city[0]},{city[1]}&limit=5&appid={api_key}")
IndexError: tuple index out of range
weather_open.py | [INFO] | 2022-09-12 22:27:50,369 | __main__ | : Fine in weather_open:120
log_setup.py | [INFO] | 2022-09-12 22:28:38,389 | __main__ | : Log Setup Completed, called from weather_open in log_setup:54
weather_open.py | [INFO] | 2022-09-12 22:28:38,635 | __main__ | : Inizio in weather_open:109
weather_open.py | [INFO] | 2022-09-12 22:28:41,946 | __main__ | : Fine in weather_open:120
log_setup.py | [INFO] | 2022-09-13 22:25:39,130 | __main__ | : Log Setup Completed, called from weather_open in log_setup:54
weather_open.py | [INFO] | 2022-09-13 22:25:40,094 | __main__ | : Inizio in weather_open:109
weather_open.py | [INFO] | 2022-09-13 22:25:43,576 | __main__ | : Fine in weather_open:120
log_setup.py | [INFO] | 2023-07-22 19:16:49,959 | __main__ | : Log Setup Completed, called from weather_open in log_setup:54
weather_open.py | [INFO] | 2023-07-22 19:16:50,708 | __main__ | : Inizio in weather_open:120
weather_open.py | [INFO] | 2023-07-22 19:16:53,925 | __main__ | : Fine in weather_open:131
